Workbook

Sheet Base e QC
A1: # | B1: Loja | C1: Index | D1: ID do Anúncio | E1: Nome do Anúncio | F1: Impressões | G1: Cliques | H1: CTR | I1: Conversões | J1: Custo por Conversão | K1: Taxa de Conversão | L1: Itens Vendidos | M1: GMV | N1: Despesas | O1: ACOS | P1: Categoria | Q1: Tamanho | R1: Qtd | S1: % Lucro Médio P | T1: lucro liquido | U1: % Lucro | V1: índice
A2: 28 | B2: 1 | C2: A4+A3 | D2: 21997807147 | E2: Kit 6 Bases de Corte (3 un A3 + 3 unidades A4 Paisagem) + 1 Refil de cola Universal 50g | F2: 167 | G2: 0 | H2: 0 | I2: 0 | J2: 0 | K2: 0 | L2: 0 | M2: 0 | N2: 0 | O2: 0 | P2: Base de Corte | Q2: A4 + A3 | R2: 6 | S2: 0.3 | T2: =+S2*M2 -> 0 | U2: =+T2/M2 -> #DIV/0! | V2: =+T2*U2 -> #DIV/0!
A3: 6 | B3: 1 | C3: Base 30x30 | D3: 23092653904 | E3: Base de Corte 30x30 Transparente COMPATIVEL Silhouette Cameo 1, 2, 3 4, 5 Plus e Pro - Com Cola | F3: 5958 | G3: 108 | H3: 0.0181 | I3: 12 | J3: 2.57 | K3: 0.1111 | L3: 14 | M3: 460.6 | N3: 30.84 | O3: 0.0669 | P3: Base de Corte | Q3: 30x30 | R3: 1 | S3: 0.35413153 | T3: =+S3*M3 -> 163.11298 | U3: =+T3/M3 -> 0.35413153 | V3: =+T3*U3 -> 57.763451
A4: 7 | B4: 1 | C4: Base 30x30 | D4: 22393068915 | E4: Base de Corte 30x30 Transparente Compativel Silhouette Cameo 1, 2, 3 e 4 Cola Refil 50g | F4: 6299 | G4: 49 | H4: 0.0078 | I4: 6 | J4: 3.17 | K4: 0.1224 | L4: 6 | M4: 349.4 | N4: 19 | O4: 0.0544 | P4: Base de Corte | Q4: 30x30 | R4: 1 | S4: 0.35413153 | T4: =+S4*M4 -> 123.73356 | U4: =+T4/M4 -> 0.35413153 | V4: =+T4*U4 -> 43.817955
A5: 18 | B5: 1 | C5: Base 30x30 | D5: 23897145567 | E5: KIT 2 Base de Corte 30x30 Transparente COMPATIVEL Silhouette Cameo 2, 3 - Com Cola | F5: 10249 | G5: 106 | H5: 0.0103 | I5: 5 | J5: 7.83 | K5: 0.0472 | L5: 6 | M5: 399.4 | N5: 39.13 | O5: 0.098 | P5: Base de Corte | Q5: 30x30 | R5: 2 | S5: 0.35602573 | T5: =+S5*M5 -> 142.19667 | U5: =+T5/M5 -> 0.35602573 | V5: =+T5*U5 -> 50.625674
A6: 19 | B6: 1 | C6: Base 30x30 | D6: 23092653852 | E6: Kit 2 Base de Corte 30x30 Transparente Compativel Silhouette, Cameo - Com Cola Alta Fixação | F6: 10452 | G6: 151 | H6: 0.0144 | I6: 25 | J6: 3.04 | K6: 0.1656 | L6: 26 | M6: 1297.4 | N6: 75.98 | O6: 0.0586 | P6: Base de Corte | Q6: 30x30 | R6: 2 | S6: 0.35602573 | T6: =+S6*M6 -> 461.90778 | U6: =+T6/M6 -> 0.35602573 | V6: =+T6*U6 -> 164.45105
A7: 23 | B7: 1 | C7: Base 30x30 | D7: 17507436448 | E7: Kit 2 Bases De Corte 30x30 Compativel Silhouette Cameo com Cola | F7: 7333 | G7: 77 | H7: 0.0105 | I7: 5 | J7: 5.12 | K7: 0.0649 | L7: 5 | M7: 349.5 | N7: 25.59 | O7: 0.0732 | P7: Base de Corte | Q7: 30x30 | R7: 2 | S7: 0.35602573 | T7: =+S7*M7 -> 124.43099 | U7: =+T7/M7 -> 0.35602573 | V7: =+T7*U7 -> 44.300634
A8: 26 | B8: 1 | C8: Base 30x30 | D8: 19699244794 | E8: Kit 4 Bases de Corte 30x30 Transparente + 1 Cola de Reposição 50g - Para Silhouette Cameo Compatível | F8: 4968 | G8: 52 | H8: 0.0105 | I8: 5 | J8: 6.86 | K8: 0.0962 | L8: 5 | M8: 597.5 | N8: 34.3 | O8: 0.0574 | P8: Base de Corte | Q8: 30x30 | R8: 4 | S8: 0.37342069 | T8: =+S8*M8 -> 223.11886 | U8: =+T8/M8 -> 0.37342069 | V8: =+T8*U8 -> 83.3172
A9: 40 | B9: 2 | C9: Base 30x30 | D9: 20897672485 | E9: 2 Base de Corte 30x30 Transparente Para Silhouette Cameo, Cameo 2 3 4, 4 Plus e 4 Pro - Com e Sem Cola [3] | F9: 75988 | G9: 1544 | H9: 2.03% | I9: 200 | J9: 4.04 | K9: 12.95% | L9: 206 | M9: 10612.52 | N9: 808.29 | O9: 7.62% | P9: Base de Corte | Q9: 30x30 | R9: 2 | S9: 0.35602573 | T9: =+S9*M9 -> 3778.3301 | U9: =+T9/M9 -> 0.35602573 | V9: =+T9*U9 -> 1345.1827
A10: 44 | B10: 2 | C10: Base 30x30 | D10: 21397167338 | E10: 1 Base de Corte 30x30 Para Silhouette Cameo, Cameo 1 2 3 4, 4 Plus e 4 Pro - Versão Com Cola e Sem Cola - 0,40mm [5] | F10: 34950 | G10: 818 | H10: 2.34% | I10: 121 | J10: 2.04 | K10: 14.79% | L10: 125 | M10: 3726.5 | N10: 246.36 | O10: 6.61% | P10: Base de Corte | Q10: 30x30 | R10: 1 | S10: 0.35413153 | T10: =+S10*M10 -> 1319.6712 | U10: =+T10/M10 -> 0.35413153 | V10: =+T10*U10 -> 467.33717
A11: 51 | B11: 2 | C11: Base 30x30 | D11: 22397598129 | E11: Base de corte 30x30 Silhouette Portrait 1, 2, e 3 Transparente Com e Sem Cola [2] | F11: 15990 | G11: 303 | H11: 1.89% | I11: 25 | J11: 3.75 | K11: 8.25% | L11: 25 | M11: 846.5 | N11: 93.83 | O11: 11.08% | P11: Base de Corte | Q11: 30x30 | R11: 1 | S11: 0.35413153 | T11: =+S11*M11 -> 299.77234 | U11: =+T11/M11 -> 0.35413153 | V11: =+T11*U11 -> 106.15884
A12: 55 | B12: 2 | C12: Base 30x30 | D12: 23192993710 | E12: Kit 2 Base de Corte 30x30 Transparente + 1 Cola Refil Base 50g - Compativel Silhouette Portrait, Portrait 2, 3 [3] | F12: 11790 | G12: 156 | H12: 1.32% | I12: 22 | J12: 4.48 | K12: 14.10% | L12: 22 | M12: 1362.3 | N12: 98.59 | O12: 7.24% | P12: Base de Corte | Q12: 30x30 | R12: 2 | S12: 0.35602573 | T12: =+S12*M12 -> 485.01385 | U12: =+T12/M12 -> 0.35602573 | V12: =+T12*U12 -> 172.67741
A13: 58 | B13: 2 | C13: Base 30x30 | D13: 23597490298 | E13: kit 4 Esteira de Corte 30x30 Transparente + 1 Cola Base 50g Compativel Silhouette Portrait 2 e 3 Cameo [3] | F13: 11076 | G13: 153 | H13: 1.38% | I13: 13 | J13: 7.02 | K13: 8.50% | L13: 13 | M13: 1175.8 | N13: 91.28 | O13: 7.76% | P13: Base de Corte | Q13: 30x30 | R13: 4 | S13: 0.37342069 | T13: =+S13*M13 -> 439.06805 | U13: =+T13/M13 -> 0.37342069 | V13: =+T13*U13 -> 163.95709
A14: 12 | B14: 1 | C14: Base 30x30 CM | D14: 13869340936 | E14: Base de Corte C/Cola 30x30 Brother Scanncut - Cm300 (Espessura: 30mm) | F14: 8898 | G14: 211 | H14: 0.0237 | I14: 17 | J14: 4.12 | K14: 0.0806 | L14: 18 | M14: 664.2 | N14: 70 | O14: 0.1054 | P14: Base de Corte | Q14: 30x30 Scanncut | R14: 1 | S14: 0.3887618 | T14: =+S14*M14 -> 258.21559 | U14: =+T14/M14 -> 0.3887618 | V14: =+T14*U14 -> 100.38436
A15: 15 | B15: 1 | C15: Base 30x30 CM | D15: 15037739365 | E15: Brother ScanNCut - Base de Corte 30x30cm - Compatível com CM300, CM550 e CM650 | F15: 7279 | G15: 176 | H15: 0.0242 | I15: 9 | J15: 4.23 | K15: 0.0511 | L15: 9 | M15: 331.2 | N15: 38.04 | O15: 0.1148 | P15: Base de Corte | Q15: 30x30 Scanncut | R15: 1 | S15: 0.3887618 | T15: =+S15*M15 -> 128.75791 | U15: =+T15/M15 -> 0.3887618 | V15: =+T15*U15 -> 50.056156
A16: 17 | B16: 1 | C16: Base 30x30 CM | D16: 15833567190 | E16: Esteira De Corte 30x30 Para Brother Scanncut CM300, CM550 e CM650 - Envio Imediato! | F16: 30225 | G16: 1114 | H16: 0.0369 | I16: 62 | J16: 2.44 | K16: 0.0557 | L16: 64 | M16: 2315.9 | N16: 151.02 | O16: 0.0652 | P16: Base de Corte | Q16: 30x30 Scanncut | R16: 1 | S16: 0.3887618 | T16: =+S16*M16 -> 900.33345 | U16: =+T16/M16 -> 0.3887618 | V16: =+T16*U16 -> 350.01525
A17: 42 | B17: 2 | C17: Base 30x30 SDX | D17: 22792913222 | E17: 1 Base de Corte 30x30 Com Cola para ScanNcut SDX 85, 125 e 225 - Envio Expresso [3] | F17: 36365 | G17: 928 | H17: 2.55% | I17: 59 | J17: 4.67 | K17: 6.36% | L17: 62 | M17: 4001.69 | N17: 275.75 | O17: 6.89% | P17: Base de Corte | Q17: 30x30 SDX | R17: 1 | S17: 0.46083641 | T17: =+S17*M17 -> 1844.1245 | U17: =+T17/M17 -> 0.46083641 | V17: =+T17*U17 -> 849.8397
A18: 8 | B18: 1 | C18: Base 30x60 | D18: 11714995653 | E18: Base De Corte 30x60 Com Cola Compatível com Silhouette Cameo - Plotters Qualidade Original | F18: 8226 | G18: 185 | H18: 0.0225 | I18: 11 | J18: 4.4 | K18: 0.0595 | L18: 11 | M18: 512.9 | N18: 48.37 | O18: 0.0943 | P18: Base de Corte | Q18: 30x60 | R18: 1 | S18: 0.31733086 | T18: =+S18*M18 -> 162.759 | U18: =+T18/M18 -> 0.31733086 | V18: =+T18*U18 -> 51.648454
A19: 10 | B19: 1 | C19: Base 30x60 | D19: 22891613667 | E19: Base de Corte 30x60 Para Silhouette Cameo, Cameo 2 3 4 e 4 Plus - Com Cola e Sem Cola - 40mm e 30mm | F19: 7003 | G19: 87 | H19: 0.0124 | I19: 5 | J19: 5.23 | K19: 0.0575 | L19: 5 | M19: 229.3 | N19: 26.13 | O19: 0.114 | P19: Base de Corte | Q19: 30x60 | R19: 1 | S19: 0.31733086 | T19: =+S19*M19 -> 72.763967 | U19: =+T19/M19 -> 0.31733086 | V19: =+T19*U19 -> 23.090252
A20: 14 | B20: 1 | C20: Base 30x60 | D20: 15657461060 | E20: Base de Corte para Silhouette Cameo Bannercut 30x60 Com Cola Alta fixação e durabilidade | F20: 7543 | G20: 127 | H20: 0.0168 | I20: 8 | J20: 3.35 | K20: 0.063 | L20: 8 | M20: 367.2 | N20: 26.81 | O20: 0.073 | P20: Base de Corte | Q20: 30x60 | R20: 1 | S20: 0.31733086 | T20: =+S20*M20 -> 116.52389 | U20: =+T20/M20 -> 0.31733086 | V20: =+T20*U20 -> 36.976627
A21: 27 | B21: 1 | C21: Base 30x60 | D21: 22298698288 | E21: KIT 5 placa - Base de Corte 30x60 - com Cola - compatível mesa Transparente | F21: 2578 | G21: 18 | H21: 0.007 | I21: 0 | J21: 0 | K21: 0 | L21: 0 | M21: 0 | N21: 10.18 | O21: 0 | P21: Base de Corte | Q21: 30x60 | R21: 5 | S21: 0.29684227 | T21: =+S21*M21 -> 0 | U21: =+T21/M21 -> #DIV/0! | V21: =+T21*U21 -> #DIV/0!
A22: 52 | B22: 2 | C22: Base 30x60 | D22: 22392895533 | E22: Base de Corte 30x60 Para Cameo Silhouette - Espessura Original - Corte Com Precisão - Com Cola [3] | F22: 14429 | G22: 249 | H22: 1.73% | I22: 22 | J22: 5 | K22: 8.84% | L22: 25 | M22: 1325.74 | N22: 110.08 | O22: 8.30% | P22: Base de Corte | Q22: 30x60 | R22: 1 | S22: 0.31733086 | T22: =+S22*M22 -> 420.69822 | U22: =+T22/M22 -> 0.31733086 | V22: =+T22*U22 -> 133.50053
A23: 57 | B23: 2 | C23: Base 30x60 | D23: 22392890747 | E23: 1 Esteira Base de Corte 30x60 Para Plotters Cameo Silhouette [2] | F23: 11393 | G23: 250 | H23: 2.19% | I23: 13 | J23: 4.54 | K23: 5.20% | L23: 13 | M23: 582.86 | N23: 58.99 | O23: 10.12% | P23: Base de Corte | Q23: 30x60 | R23: 1 | S23: 0.31733086 | T23: =+S23*M23 -> 184.95947 | U23: =+T23/M23 -> 0.31733086 | V23: =+T23*U23 -> 58.693347
A24: 9 | B24: 1 | C24: Base 30x60 SDX | D24: 15250252385 | E24: Base de Corte 30x60 Com Cola para Brother SDX 85, SDX 125 e SDX 225 - Envio Expresso | F24: 18785 | G24: 567 | H24: 0.0302 | I24: 36 | J24: 3.45 | K24: 0.0635 | L24: 38 | M24: 1640.2 | N24: 124.13 | O24: 0.0757 | P24: Base de Corte | Q24: 30x60 SDX | R24: 1 | S24: 0.33723319 | T24: =+S24*M24 -> 553.12988 | U24: =+T24/M24 -> 0.33723319 | V24: =+T24*U24 -> 186.53375
A25: 77 | B25: 3 | C25: Base 30x60 SDX | D25: 23329850370 | E25: Base de Corte Sem Cola 30x60 Para Brother SDX 85, 125 e 225 Espessura original Rigidez [3] | F25: 9349 | G25: 236 | H25: 2.52% | I25: 13 | J25: 3.99 | K25: 0.0551 | L25: 13 | M25: 713.12 | N25: 51.83 | O25: 0.0727 | P25: Base de Corte | Q25: 30x60 SDX Sem Cola | R25: 1 | S25: 0.31108802 | T25: =+S25*M25 -> 221.84309 | U25: =+T25/M25 -> 0.31108802 | V25: =+T25*U25 -> 69.012727
A26: 62 | B26: 2 | C26: Base 90x60 | D26: 22692878658 | E26: Base de corte 90x60 P/plotters Profissionais Silhouete Cameo 4, Cameo 4 Plus e Cameo Pro e outros modelos [3] | F26: 8148 | G26: 229 | H26: 2.81% | I26: 5 | J26: 7.17 | K26: 2.18% | L26: 5 | M26: 397.9 | N26: 35.84 | O26: 9.01% | P26: Base de Corte | Q26: 60x90 | R26: 1 | S26: 0.3421049 | T26: =+S26*M26 -> 136.12354 | U26: =+T26/M26 -> 0.3421049 | V26: =+T26*U26 -> 46.568529
A27: 4 | B27: 1 | C27: Base A3 | D27: 17936580203 | E27: 2 Bases de Corte Para Silhouette Cameo A3 Com Cola | F27: 5968 | G27: 74 | H27: 0.0124 | I27: 6 | J27: 5.19 | K27: 0.0811 | L27: 6 | M27: 401.4 | N27: 31.15 | O27: 0.0776 | P27: Base de Corte | Q27: A3 | R27: 2 | S27: 0.38135257 | T27: =+S27*M27 -> 153.07492 | U27: =+T27/M27 -> 0.38135257 | V27: =+T27*U27 -> 58.375515
A28: 5 | B28: 1 | C28: Base A3 | D28: 22698704717 | E28: 4 bases de Corte Cameo A3 Com Cola - Plotter Silhouette Qualidade Original Alta rigidez | F28: 5536 | G28: 40 | H28: 0.0072 | I28: 0 | J28: 0 | K28: 0 | L28: 0 | M28: 0 | N28: 3.34 | O28: 0 | P28: Base de Corte | Q28: A3 | R28: 4 | S28: 0.34723323 | T28: =+S28*M28 -> 0 | U28: =+T28/M28 -> #DIV/0! | V28: =+T28*U28 -> #DIV/0!
A29: 50 | B29: 2 | C29: Base A3 | D29: 23092924234 | E29: 1 Base de Corte A3 Branca Para Plotters Cameo Silhouette E Outros Modelos Confira - Com Cola [2] | F29: 17819 | G29: 339 | H29: 1.90% | I29: 35 | J29: 3.23 | K29: 10.32% | L29: 39 | M29: 1372.1 | N29: 113 | O29: 8.24% | P29: Base de Corte | Q29: A3 | R29: 1 | S29: 0.38388479 | T29: =+S29*M29 -> 526.72832 | U29: =+T29/M29 -> 0.38388479 | V29: =+T29*U29 -> 202.20299
A30: 73 | B30: 3 | C30: Base A3 | D30: 22629854054 | E30: Base de Corte A3 Com Cola Para Cameo Silhouette Artesanato - Compatibilidade Universal [4] | F30: 19342 | G30: 429 | H30: 2.22% | I30: 55 | J30: 2.84 | K30: 0.1282 | L30: 58 | M30: 1907.25 | N30: 156.36 | O30: 0.082 | P30: Base de Corte | Q30: A3 | R30: 1 | S30: 0.38388479 | T30: =+S30*M30 -> 732.16427 | U30: =+T30/M30 -> 0.38388479 | V30: =+T30*U30 -> 281.06673
A31: 1 | B31: 1 | C31: Base A4 | D31: 22398484368 | E31: 10 Mesa de corte base A4 - Alta Rigidez - resistente branco Poliester cristal | F31: 1302 | G31: 4 | H31: 0.0031 | I31: 1 | J31: 1.35 | K31: 0.25 | L31: 1 | M31: 77.9 | N31: 1.35 | O31: 0.0173 | P31: Base de Corte | Q31: A4 | R31: 10 | S31: 0.41310476 | T31: =+S31*M31 -> 32.180861 | U31: =+T31/M31 -> 0.41310476 | V31: =+T31*U31 -> 13.294067
A32: 2 | B32: 1 | C32: Base A4 | D32: 23697297381 | E32: 2 Base de Corte A4 Transparente +1 Cola Reposição Para Base 50g Para Silhouette Portrait 1,2, 3 e 4 Cameo 2 e 3 Com Cola | F32: 33399 | G32: 653 | H32: 0.0196 | I32: 90 | J32: 3.07 | K32: 0.1378 | L32: 90 | M32: 3828.68 | N32: 276.51 | O32: 0.0722 | P32: Base de Corte | Q32: A4 | R32: 2 | S32: 0.40691701 | T32: =+S32*M32 -> 1557.955 | U32: =+T32/M32 -> 0.40691701 | V32: =+T32*U32 -> 633.95838
A33: 3 | B33: 1 | C33: Base A4 | D33: 22694202713 | E33: 2 Bases de Corte A4 Compatível Silhouette Portrait 1,2,3 - Alta Rigidez Com Cola - Cameo | F33: 21575 | G33: 525 | H33: 0.0243 | I33: 51 | J33: 2.6 | K33: 0.0971 | L33: 51 | M33: 1791.68 | N33: 132.68 | O33: 0.0741 | P33: Base de Corte | Q33: A4 | R33: 2 | S33: 0.40691701 | T33: =+S33*M33 -> 729.06506 | U33: =+T33/M33 -> 0.40691701 | V33: =+T33*U33 -> 296.66897
A34: 11 | B34: 1 | C34: Base A4 | D34: 23597556517 | E34: Base de corte A4 Silhouette e Cameo 1 a 5 - Alta Durabilidade - Com ou Sem Cola | F34: 5422 | G34: 58 | H34: 0.0107 | I34: 7 | J34: 3.14 | K34: 0.1207 | L34: 8 | M34: 404.2 | N34: 21.95 | O34: 0.0543 | P34: Base de Corte | Q34: A4 | R34: 1 | S34: 0.38517754 | T34: =+S34*M34 -> 155.68876 | U34: =+T34/M34 -> 0.38517754 | V34: =+T34*U34 -> 59.967813
A35: 20 | B35: 1 | C35: Base A4 | D35: 20997495267 | E35: Kit 2 Base de Corte A4 Para Silhouette Portrait 2, 3 e 4 - Cameo, Cameo 2 e 3 - Com Cola | F35: 30716 | G35: 478 | H35: 0.0156 | I35: 57 | J35: 2.76 | K35: 0.1192 | L35: 58 | M35: 2304.6 | N35: 157.25 | O35: 0.0682 | P35: Base de Corte | Q35: A4 | R35: 2 | S35: 0.40691701 | T35: =+S35*M35 -> 937.78093 | U35: =+T35/M35 -> 0.40691701 | V35: =+T35*U35 -> 381.59901
A36: 21 | B36: 1 | C36: Base A4 | D36: 20997495263 | E36: Kit 2 Base de Corte A4 Transparente Silhouette Portrait, Portrait 2, 3 Cameo, Cameo 2 e 3 Com Cola | F36: 10484 | G36: 176 | H36: 0.0168 | I36: 21 | J36: 2.78 | K36: 0.1193 | L36: 21 | M36: 729.9 | N36: 58.43 | O36: 0.08 | P36: Base de Corte | Q36: A4 | R36: 2 | S36: 0.40691701 | T36: =+S36*M36 -> 297.00872 | U36: =+T36/M36 -> 0.40691701 | V36: =+T36*U36 -> 120.8579
A37: 25 | B37: 1 | C37: Base A4 | D37: 20997495265 | E37: Kit 4 Base de Corte A4 Transparente 1 Cola 50g Silhouette Portrait 2, 3 e 4 Papelaria e Escritório | F37: 43595 | G37: 665 | H37: 0.0153 | I37: 59 | J37: 5.04 | K37: 0.0887 | L37: 60 | M37: 4349 | N37: 297.24 | O37: 0.0683 | P37: Base de Corte | Q37: A4 | R37: 4 | S37: 0.37602001 | T37: =+S37*M37 -> 1635.311 | U37: =+T37/M37 -> 0.37602001 | V37: =+T37*U37 -> 614.90966
A38: 39 | B38: 2 | C38: Base A4 | D38: 23992823283 | E38: Kit 2 Bases A4 Transparentes Para Silhouette Portrait, Portrait 1, 2, 3 - Cameo, Cameo 2 e 3 - Com Cola [2] | F38: 158621 | G38: 3641 | H38: 2.30% | I38: 565 | J38: 2.25 | K38: 15.52% | L38: 575 | M38: 18534.15 | N38: 1269.58 | O38: 6.85% | P38: Base de Corte | Q38: A4 | R38: 2 | S38: 0.40691701 | T38: =+S38*M38 -> 7541.8608 | U38: =+T38/M38 -> 0.40691701 | V38: =+T38*U38 -> 3068.9114
A39: 41 | B39: 2 | C39: Base A4 | D39: 22893234695 | E39: Base de Corte Silhouette PORTRAIT e Silhouette CAMEO - Compatível Com Todos Os Modelos - COM COLA [3] | F39: 47196 | G39: 1130 | H39: 2.39% | I39: 119 | J39: 2.74 | K39: 10.53% | L39: 128 | M39: 3979.2 | N39: 325.83 | O39: 8.19% | P39: Base de Corte | Q39: A4 | R39: 1 | S39: 0.38517754 | T39: =+S39*M39 -> 1532.6985 | U39: =+T39/M39 -> 0.38517754 | V39: =+T39*U39 -> 590.36102
A40: 43 | B40: 2 | C40: Base A4 | D40: 23997480409 | E40: Base de corte A4 Silhouette Portrait 1, 2, 3 - Cameo Transparente Com e Sem Cola [3] | F40: 35186 | G40: 725 | H40: 2.06% | I40: 110 | J40: 2.37 | K40: 15.17% | L40: 111 | M40: 3825.21 | N40: 260.22 | O40: 6.80% | P40: Base de Corte | Q40: A4 | R40: 1 | S40: 0.38517754 | T40: =+S40*M40 -> 1473.385 | U40: =+T40/M40 -> 0.38517754 | V40: =+T40*U40 -> 567.51479
...

Sheet Resumo
A1: Resumo - Base e Esteira de Corte
A3: Anúncios filtrados | C3: =COUNTA('Base e QC'!D2:D29) -> 28
A4: Investimento (Despesas) | C4: =SUM('Base e QC'!N2:N29) -> 2737.85
A5: GMV | C5: =SUM('Base e QC'!M2:M29) -> 36033.13
A6: ROAS médio ponderado | C6: =IFERROR(C5/C4,0) -> 13.161105
A7: ACOS médio ponderado | C7: =IFERROR(C4/C5,0) -> 0.075981465
A8: Cliques | C8: =SUM('Base e QC'!G2:G29) -> 8347
A9: Conversões | C9: =SUM('Base e QC'!I2:I29) -> 740
A10: CTR médio ponderado | C10: =IFERROR(C8/C11,0) -> 0.021144279
A11: Impressões | C11: =SUM('Base e QC'!F2:F29) -> 394764
A13: ID do Anúncio | B13: Nome do Anúncio | C13: GMV | D13: Despesas | E13: ROAS | F13: ACOS | G13: Cliques | H13: Conversões
A14: 20997495265 | B14: Kit 4 Base de Corte A4 Transparente 1 Cola 50g Silhouette Portrait 2, 3 e 4 Papelaria e Escritório [2] | C14: 4349 | D14: 297.24 | E14: 14.63 | F14: 0.0683 | G14: 665 | H14: 59
A15: 23697297381 | B15: 2 Base de Corte A4 Transparente +1 Cola Reposição Para Base 50g Para Silhouette Portrait 1,2, 3 e 4 Cameo 2 e 3 Com Cola [3] | C15: 3828.68 | D15: 276.51 | E15: 13.85 | F15: 0.0722 | G15: 653 | H15: 90
A16: 15833567190 | B16: Esteira De Corte 30x30 Para Brother Scanncut CM300, CM550 e CM650 - Envio Imediato! [5] | C16: 2315.9 | D16: 151.02 | E16: 15.33 | F16: 0.0652 | G16: 1114 | H16: 62
A17: 20997495267 | B17: Kit 2 Base de Corte A4 Para Silhouette Portrait 2, 3 e 4 - Cameo, Cameo 2 e 3 - Com Cola [3] | C17: 2304.6 | D17: 157.25 | E17: 14.66 | F17: 0.0682 | G17: 478 | H17: 57
A18: 22694202713 | B18: 2 Bases de Corte A4 Compatível Silhouette Portrait 1,2,3 - Alta Rigidez Com Cola - Cameo | C18: 1791.68 | D18: 132.68 | E18: 13.5 | F18: 0.0741 | G18: 525 | H18: 51
A19: 15250252385 | B19: Base de Corte 30x60 Com Cola para Brother SDX 85, SDX 125 e SDX 225 - Envio Expresso [7] | C19: 1640.2 | D19: 124.13 | E19: 13.21 | F19: 0.0757 | G19: 567 | H19: 36
A20: 23092653852 | B20: Kit 2 Base de Corte 30x30 Transparente Compativel Silhouette, Cameo - Com Cola Alta Fixação [2] | C20: 1297.4 | D20: 75.98 | E20: 17.08 | F20: 0.0586 | G20: 151 | H20: 25
A21: 22097387599 | B21: Base de Corte Paisagem COMPATIVEL Silhouette Cameo, Cameo 1, 2, 3 E 4 - Com Cola [2] | C21: 919.4 | D21: 87.23 | E21: 10.54 | F21: 0.0949 | G21: 410 | H21: 38
A22: 20997495263 | B22: Kit 2 Base de Corte A4 Transparente Silhouette Portrait, Portrait 2, 3 Cameo, Cameo 2 e 3 Com Cola [2] | C22: 729.9 | D22: 58.43 | E22: 12.49 | F22: 0.08 | G22: 176 | H22: 21
A23: 19799037778 | B23: Cola para Base de Corte Silhouette e ScanNCut - Permanente - Fácil Aplicação - Reposição - 50g [2] | C23: 684.15 | D23: 55.04 | E23: 12.43 | F23: 0.0804 | G23: 128 | H23: 18
